Workbook
Name \0: #REF!
Name \a: #REF!
Name \b: #REF!
Name \b1: [1]MEDIÇÃO!#REF!
Name \c: #REF!
Name \CC: #REF!
Name \D: #REF!
Name \e: #REF!
Name \f: #REF!
Name \i: #REF!
Name \j: #REF!
Name \l: #REF!
Name \M: #REF!
Name \M1: [1]MEDIÇÃO!#REF!
Name \M10: #REF!
Name \M11: #REF!
Name \M12: #REF!
Name \M13: #REF!
Name \M2: #REF!
Name \M3: #REF!
Name \M4: #REF!
Name \M5: #REF!
Name \M6: #REF!
Name \M7: #REF!
Name \M8: #REF!
Name \M9: #REF!
Name \MM: #REF!
Name \O: #REF!
Name \p: [2]DETAILS!#REF!
Name \PP: #REF!
Name \q: #REF!
Name \R: #REF!
Name \s: #REF!
Name \T: #REF!
Name \y: #REF!
Name \z: #REF!
Name __________CAB1: #REF!
Name __________LOC1: #REF!
Name _________ANT1202: [3]FaixasCrit!#REF!
Name _________ANT1203: [3]FaixasCrit!#REF!
Name _________CAB1: #REF!
Name _________LOC1: #REF!
Name _________LOC10: '[4]MEDIÇAO 1'!#REF!
Name _________LOC11: '[4]MEDIÇAO 1'!#REF!
Name _________LOC12: '[4]MEDIÇAO 1'!#REF!
Name _________LOC13: '[4]MEDIÇAO 1'!#REF!
Name _________LOC14: '[4]MEDIÇAO 1'!#REF!
Name _________LOC15: '[4]MEDIÇAO 1'!#REF!
Name _________LOC16: '[4]MEDIÇAO 1'!#REF!
Name _________LOC17: '[4]MEDIÇAO 1'!#REF!
Name _________LOC18: '[4]MEDIÇAO 1'!#REF!
Name _________LOC19: '[4]MEDIÇAO 1'!#REF!
Name _________LOC2: '[4]MEDIÇAO 1'!#REF!
Name _________LOC20: '[4]MEDIÇAO 1'!#REF!
Name _________LOC21: '[4]MEDIÇAO 1'!#REF!
Name _________LOC22: '[4]MEDIÇAO 1'!#REF!
Name _________LOC23: '[4]MEDIÇAO 1'!#REF!
Name _________LOC24: '[4]MEDIÇAO 1'!#REF!
Name _________LOC25: '[4]MEDIÇAO 1'!#REF!
Name _________LOC26: '[4]MEDIÇAO 1'!#REF!

Sheet Dashboard
B2: Dados Básicos do Projeto | C2: Cliente | D2: FRIGELAR | J2: Custos Serviços | K2: Grupo de Custo | L2: Valor | M2: % Custo | N2: % PV | R2: Venda | S2: Preço de Venda | Y2: Parâmetros de Mão de Obra Precificada
K3: Mão de Obra Indireta | L3: =Precificação!U4 -> 17160 | M3: =IFERROR(L3/$L$36,0) -> 0.016341739 | S3: Serviços | T3: =ROUND(L28*(1+D35),2) -> 1278817.6
C4: Projeto | D4: FRIGELAR_GERENCIAMENTO DE OBRA | K4: Mão de Obra Direta | L4: =Precificação!U91 -> 555080 | M4: =IFERROR(L4/$L$36,0) -> 0.52861145 | S4: Materiais para revenda | T4: =SUMIF(Tarefas!$AA$32:$AA$54,"Revenda",Tarefas!$AN$32:$AN$54) -> 0 | X4: =T9/X6-1 -> -0.27785842 | Y4: Venda M.O. | Z4: R$ Homem x mês | AA4: =IFERROR(T3/(SUMPRODUCT(Precificação!L6:L89,Precificação!M6:M89)+SUMPRODUCT(Precificação!L95:L587,Precificação!M95:M587)),0) -> 29290.372
K5: Mão de Obra Direta (rotina) | L5: =Precificação!U535 -> 0 | M5: =IFERROR(L5/$L$36,0) -> 0 | S5: Materiais de Aplicação | T5: =SUMIF(Tarefas!$AA$32:$AA$54,"Aplicação",Tarefas!$AN$32:$AN$54) -> 0 | X5: =X6-T9 -> 591128.24 | Z5: R$ HH Produtivo | AA5: =IFERROR(T3/AA14,0) -> 154.69468
C6: Unidade | D6: CABREÚVA | K6: Encargos Sociais - Mensalistas | L6: =Precificação!U589 -> 85085.251 | M6: =IFERROR(L6/$L$36,0) -> 0.081028028 | S6: Faturamento Direto | T6: =SUMIF(Tarefas!$AA$32:$AA$54,"FD",Tarefas!$AN$32:$AN$54) -> 0 | X6: 2127444 | Z6: R$ HH Total | AA6: =IFERROR(T3/AA16,0) -> 151.29324
K7: Encargos Sociais - Horistas | L7: =Precificação!U627 -> 0 | M7: =IFERROR(L7/$L$36,0) -> 0 | S7: Serviço Terceirizado | T7: =SUMIF(Tarefas!$AA$32:$AA$54,"Serviço",Tarefas!$AN$32:$AN$54) -> 257498.17
C8: Localidade | D8: Município | F8: UF | K8: Mobilização/ Integração de Mão de Obra | L8: =Precificação!U665 -> 0 | M8: =IFERROR(L8/$L$36,0) -> 0 | Y8: Horas Trabalhadas | Z8: Horas Normais MOI | AA8: =SUMPRODUCT(Precificação!$L$7:$L$89,Precificação!$M$7:$M$89)*Dashboard!$D$15 -> 185.856
D9: CABREÚVA | F9: SP | K9: Desmobilização de Mão de Obra | L9: =Precificação!U683 -> 0 | M9: =IFERROR(L9/$L$36,0) -> 0 | S9: Preço de Venda | T9: =SUM(T3:T7) -> 1536315.8 | Z9: Horas Extras MOI | AA9: =SUMPRODUCT(Precificação!$L$7:$L$89,Precificação!$M$7:$M$89,Precificação!$BM$7:$BM$89)+SUMPRODUCT(Precificação!$L$7:$L$89,Precificação!$M$7:$M$89,Precificação!$BR$7:$BR$89)+SUMPRODUCT(Precificação!$L$7:$L$89,Precificação!$M$7:$M$89,Precificação!$BW$7:$BW$89) -> 0
K10: Canteiro de Obras, Infraestrutura de Apoio e Alojamento | L10: =Precificação!U701 -> 0 | M10: =IFERROR(L10/$L$36,0) -> 0 | Q10: =T9/D13 -> 153631.58 | Z10: Horas Totais MOI | AA10: =AA8+AA9 -> 185.856
C11: Mês e ano de início | K11: Benefícios | L11: =Precificação!U815 -> 62455.76 | M11: =IFERROR(L11/$L$36,0) -> 0.059477607 | Q11: =T9 -> 1536315.8 | T11: 0
K12: Exames Médicos e Gestão da Saúde Ocupacional | L12: =Precificação!U845 -> 3915 | M12: =IFERROR(L12/$L$36,0) -> 0.0037283163 | S12: Preço por Mês | T12: =IFERROR(T9/$D$14,0) -> 153631.58 | Z12: Horas Normais MOD | AA12: =SUMPRODUCT(Precificação!$L$95:$L$587,Precificação!$M$95:$M$587)*Dashboard!$D$15 -> 8266.72
B13: Prazos | C13: Prazo do Contrato | D13: 10 | E13: meses | K13: EPI's - Equipamentos de Proteção Individual | L13: =Precificação!U857 -> 14142.384 | M13: =IFERROR(L13/$L$36,0) -> 0.013468015 | Z13: Horas Extras MOD | AA13: =SUMPRODUCT(Precificação!$L$95:$L$587,Precificação!$M$95:$M$587,Precificação!$BM$95:$BM$587)+SUMPRODUCT(Precificação!$L$95:$L$587,Precificação!$M$95:$M$587,Precificação!$BR$95:$BR$587)+SUMPRODUCT(Precificação!$L$95:$L$587,Precificação!$M$95:$M$587,Precificação!$BW$95:$BW$587) -> 0
C14: Prazo de Execução | D14: 10 | E14: meses | K14: EPC's - Equipamentos de Proteção Coletiva | L14: =Precificação!U922 -> 2464.5833 | M14: =IFERROR(L14/$L$36,0) -> 0.0023470616 | Z14: Horas Totais MOD | AA14: =AA12+AA13 -> 8266.72
C15: Carga horária mês | D15: =D16*D17 -> 193.6 | E15: horas | K15: Treinamentos | L15: =Precificação!U941 -> 0 | M15: =IFERROR(L15/$L$36,0) -> 0
C16: Dias trabalhados no mês | D16: 22 | E16: dias/mês | K16: Viagens e Hospedagem | L16: =Precificação!U967 -> 87000 | M16: =IFERROR(L16/$L$36,0) -> 0.082851474 | Z16: Horas Totais MO | AA16: =AA10+AA14 -> 8452.576
C17: Carga horária diária | D17: 8.8 | E17: horas/dia | K17: Equipamentos e Ferramentas | L17: =Precificação!U986 -> 2000 | M17: =IFERROR(L17/$L$36,0) -> 0.0019046316
K18: Equipamentos de Informática e Softwares | L18: =Precificação!U1191 -> 39989.467 | M18: =IFERROR(L18/$L$36,0) -> 0.038082601 | Y18: Relações de Mão de Obra | Z18: MOI (Máxima) | AA18: ='Cronog. e Histog.'!I851 -> 0.08
B19: Acordo Coletivo | C19: Tarifa Banco de Horas | D19: 0.5 | E19: % | K19: Veículos leves e Fretamento | L19: =Precificação!U1219 -> 0 | M19: =IFERROR(L19/$L$36,0) -> 0 | Z19: MOD (Máxima) | AA19: ='Cronog. e Histog.'!I691+'Cronog. e Histog.'!I748 -> 4.27
C20: Tarifa Hora Extra 1 | D20: 0.75 | E20: % | K20: Veículos e Equipamentos Pesados | L20: =Precificação!U1246 -> 0 | M20: =IFERROR(L20/$L$36,0) -> 0 | Z20: MO Total (Máxima) | AA20: =AA18+AA19 -> 4.35
C21: Tarifa Hora Extra 2 | D21: 1 | E21: % | K21: Materiais de Consumo | L21: =Precificação!U1378 -> 0 | M21: =IFERROR(L21/$L$36,0) -> 0
C22: Taxa de reajuste (dissídio) | D22: 0.06 | E22: % | K22: Materiais de Aplicação Gerais | L22: =Precificação!U1417 -> 0 | M22: =IFERROR(L22/$L$36,0) -> 0 | Z22: % MOI (Máxima) | AA22: =IFERROR(AA18/$AA$20,0) -> 0.018390805
C23: Carga horária base mensal | D23: 220 | E23: horas/mês | K23: Serviços Terceirizados | L23: =Precificação!U1427 -> 3929.4 | M23: =IFERROR(L23/$L$36,0) -> 0.0037420297 | Z23: % MOD (Máxima) | AA23: =IFERROR(AA19/$AA$20,0) -> 0.9816092
A24: Empreitada | B24: Faturamento Indireto | K24: Locações | L24: =Precificação!U1460 -> 0 | M24: =IFERROR(L24/$L$36,0) -> 0 | Q24: Faturamento Indireto | R24: Resultados e Análises | U24: %
B25: =IF(A24="Empreitada","Margem","Markup") -> Margem | C25: =IF(A24="Empreitada","Lucro","Taxa de Administração") -> Lucro | D25: 0.11 | E25: =SUM(D25:D28) -> 0.23 | K25: Mobilização e Desmobilização de Recursos | L25: =Precificação!U1474 -> 850 | M25: =IFERROR(L25/$L$36,0) -> 0.00080946842 | R25: Margem | S25: =IF(C25>0,C25,"") -> Lucro | T25: =IF(AND($Q$24=$B$24,$A$24="Empreitada"),D25*($T$9-$T$6),D25*(($T$9-$T$6)/(1+$D$35))) -> 168994.74 | U25: =IFERROR(T25/($T$9-$T$6),0) -> 0.11 | Z25: MOI/MOD (Média) | AA25: =IFERROR(SUM('Cronog. e Histog.'!K860:BR860)/SUM('Cronog. e Histog.'!K858:BR859),0) -> 0.022482436
C26: Overhead | D26: 0.1 | K26: Riscos e Contingências | L26: =Precificação!U1543 -> 0 | M26: =IFERROR(L26/$L$36,0) -> 0 | N26: =IFERROR(L26/$L$36,0) -> 0 | S26: =IF(C26>0,C26,"") -> Overhead | T26: =IF(AND($Q$24=$B$24,$A$24="Empreitada"),D26*($T$9-$T$6),D26*(($T$9-$T$6)/(1+$D$35))) -> 153631.58 | U26: =IFERROR(T26/($T$9-$T$6),0) -> 0.1
C27: Taxa de negociação | D27: 0.02 | K27: Outros Custos | L27: =Precificação!U1549 -> 0 | M27: =IFERROR(L27/$L$36,0) -> 0 | S27: =IF(C27>0,C27,"") -> Taxa de negociação | T27: =IF(AND($Q$24=$B$24,$A$24="Empreitada"),D27*($T$9-$T$6),D27*(($T$9-$T$6)/(1+$D$35))) -> 30726.316 | U27: =IFERROR(T27/($T$9-$T$6),0) -> 0.02
C28: Custo Financeiro | D28: 0 | K28: Custo Total - Serviços | L28: =SUM(L3:L27) -> 874071.84 | M28: =IFERROR(L28/$L$36,0) -> 0.83239242 | S28: =IF(C28>0,C28,"") -> Custo Financeiro | T28: =IF(AND($Q$24=$B$24,$A$24="Empreitada"),D28*($T$9-$T$6),D28*(($T$9-$T$6)/(1+$D$35))) -> 0 | U28: =IFERROR(T28/($T$9-$T$6),0) -> 0
R29: Valor Total - Margem | T29: =SUM(T25:T28) -> 353352.63 | U29: =SUM(U25:U28) -> 0.23
B30: Impostos (serviços) | C30: PIS | D30: 0.0065 | E30: =SUM(D30:D33) -> 0.0865 | J30: Custos Materiais/ Terceiros | K30: Materiais para revenda | L30: =SUMIF(Tarefas!$AA$32:$AA$54,"Revenda",Tarefas!$AC$32:$AC$54) -> 0 | M30: =IFERROR(L30/$L$36,0) -> 0
C31: COFINS | D31: 0.03 | K31: Materiais de Aplicação | L31: =SUMIF(Tarefas!$AA$32:$AA$54,"Aplicação",Tarefas!$AC$32:$AC$54) -> 0 | M31: =IFERROR(L31/$L$36,0) -> 0 | R31: Impostos (serviços) | S31: =IF(C30>0,C30,"") -> PIS | T31: =D30*($T$9-$T$6-$T$7) -> 8312.3145 | U31: =IFERROR(T31/$T$9,0) -> 0.0054105507
C32: ISSQN | D32: =VLOOKUP(D9,'APOIO Impostos'!L:O,2,0) -> 0.05 | K32: Faturamento Direto | L32: =SUMIF(Tarefas!$AA$32:$AA$54,"FD",Tarefas!$AC$32:$AC$54) -> 0 | M32: =IFERROR(L32/$L$36,0) -> 0 | S32: =IF(C31>0,C31,"") -> COFINS | T32: =D31*($T$9-$T$6-$T$7) -> 38364.529 | U32: =IFERROR(T32/$T$9,0) -> 0.024971773
C33: CPRB | K33: Serviço Terceirizado | L33: =SUMIF(Tarefas!$AA$32:$AA$54,"Serviço",Tarefas!$AC$32:$AC$54) -> 176000 | M33: =IFERROR(L33/$L$36,0) -> 0.16760758 | S33: =IF(C32>0,C32,"") -> ISSQN | T33: =D32*($T$9-$T$6-$T$7) -> 63940.881 | U33: =IFERROR(T33/$T$9,0) -> 0.041619621
K34: Custo Total - Materiais/ Terceiros | L34: =SUM(L30:L33) -> 176000 | M34: =IFERROR(L34/$L$36,0) -> 0.16760758 | S34: =IF(C33>0,C33,"") -> CPRB | T34: =D33*($T$9-$T$6-$T$7) -> 0 | U34: =IFERROR(T34/$T$9,0) -> 0
B35: BDI Multiplicador sobre o custo | D35: =IF(A24="Empreitada",(1/(1-E25-E30))-1,(1*(1+E25)/(1-E30))-1) -> 0.46305779 | S35: Impostos sobre Materiais | T35: =E30*($T$7) -> 22273.592
J36: Custo Total | L36: =L28+L34 -> 1050071.8 | R36: Valor Total - Impostos | T36: =SUM(T31:T35) -> 132891.32
A37: Empreitada | B37: Faturamento Direto | Q37: Faturamento Direto | R37: Resultados e Análises | U37: % | X37: A | Y37: Receita Total | Z37: =T9 -> 1536315.8 | AA37: =IFERROR(Z37/$Z$37,0) -> 1
B38: =IF(A37="Empreitada","Margem","Markup") -> Margem | C38: =IF(A37="Empreitada","Lucro","Taxa de Administração") -> Lucro | D38: =D25 -> 0.11 | E38: =SUM(D38:D41) -> 0.23 | R38: Margem | S38: =IF(C38>0,C38,"") -> Lucro | T38: =IF(AND($Q$37=$B$37,$A$37="Empreitada"),(D38/(1-$E$43)*($T$6))*(1-$E$43),D38*(($T$6)/(1+$D$48))) -> 0 | U38: =IF(AND($Q$37=$B$37,$A$37="Empreitada"),T38/($T$4),T38/(($T$4)/(1+$D$48))) -> #DIV/0! | X38: B | Y38: Impostos de Serviços | Z38: =T31+T32+T33 -> 110617.72 | AA38: =IFERROR(SUM(Z38:Z39)/$Z$37,0) -> 0.0865
C39: Overhead | D39: =D26 -> 0.1 | S39: =IF(C39>0,C39,"") -> Overhead | T39: =IF(AND($Q$37=$B$37,$A$37="Empreitada"),(D39/(1-$E$43)*($T$6))*(1-$E$43),D39*(($T$6)/(1+$D$48))) -> 0 | U39: =IF(AND($Q$37=$B$37,$A$37="Empreitada"),T39/($T$4),T39/(($T$4)/(1+$D$48))) -> #DIV/0! | X39: C | Y39: Impostos de Materiais | Z39: =T35+T49 -> 22273.592
C40: Taxa de negociação | D40: =D27 -> 0.02 | S40: =IF(C40>0,C40,"") -> Taxa de negociação | T40: =IF(AND($Q$37=$B$37,$A$37="Empreitada"),(D40/(1-$E$43)*($T$6))*(1-$E$43),D40*(($T$6)/(1+$D$48))) -> 0 | U40: =IF(AND($Q$37=$B$37,$A$37="Empreitada"),T40/($T$4),T40/(($T$4)/(1+$D$48))) -> #DIV/0! | X40: D | Y40: Custos de Serviços | Z40: =L28 -> 874071.84 | AA40: =IFERROR(SUM(Z40:Z41)/$Z$37,0) -> 0.6835
C41: Custo Financeiro | D41: =D28 -> 0 | S41: =IF(C41>0,C41,"") -> Custo Financeiro | T41: =IF(AND($Q$37=$B$37,$A$37="Empreitada"),(D41/(1-$E$43)*($T$6))*(1-$E$43),D41*(($T$6)/(1+$D$48))) -> 0 | U41: =IF(AND($Q$37=$B$37,$A$37="Empreitada"),T41/($T$4),T41/(($T$4)/(1+$D$48))) -> #DIV/0! | X41: E | Y41: Custos de Materiais | Z41: =Tarefas!AC28 -> 176000
...

Sheet Gráficos
B2: Gráficos Técnicos
B4: Avanço Físico - Curva S
B5: 1 | C5: 2 | D5: 3 | E5: 4 | F5: 5 | G5: 6 | H5: 7 | I5: 8 | J5: 9 | K5: 10 | L5: 11 | M5: 12 | N5: 13 | O5: 14 | P5: 15 | Q5: 16 | R5: 17 | S5: 18 | T5: 19 | U5: 20 | V5: 21 | W5: 22 | X5: 23 | Y5: 24 | Z5: 25 | AA5: 26 | AB5: 27 | AC5: 28 | AD5: 29 | AE5: 30 | AF5: 31 | AG5: 32 | AH5: 33 | AI5: 34 | AJ5: 35 | AK5: 36 | AL5: 37 | AM5: 38 | AN5: 39 | AO5: 40 | AP5: 41 | AQ5: 42 | AR5: 43 | AS5: 44 | AT5: 45 | AU5: 46 | AV5: 47 | AW5: 48 | AX5: 49 | AY5: 50 | AZ5: 51 | BA5: 52 | BB5: 53 | BC5: 54 | BD5: 55 | BE5: 56 | BF5: 57 | BG5: 58 | BH5: 59 | BI5: 60
B6: =IF('Cronog. e Histog.'!K97>0,'Cronog. e Histog.'!K97,#N/A) -> 0.1 | C6: =IF('Cronog. e Histog.'!L97>0,'Cronog. e Histog.'!L97,#N/A) -> 0.1 | D6: =IF('Cronog. e Histog.'!M97>0,'Cronog. e Histog.'!M97,#N/A) -> 0.1 | E6: =IF('Cronog. e Histog.'!N97>0,'Cronog. e Histog.'!N97,#N/A) -> 0.1 | F6: =IF('Cronog. e Histog.'!O97>0,'Cronog. e Histog.'!O97,#N/A) -> 0.1 | G6: =IF('Cronog. e Histog.'!P97>0,'Cronog. e Histog.'!P97,#N/A) -> 0.1 | H6: =IF('Cronog. e Histog.'!Q97>0,'Cronog. e Histog.'!Q97,#N/A) -> 0.1 | I6: =IF('Cronog. e Histog.'!R97>0,'Cronog. e Histog.'!R97,#N/A) -> 0.1 | ... BI6: =IF('Cronog. e Histog.'!BR97>0,'Cronog. e Histog.'!BR97,#N/A) -> #N/A
B7: =IF('Cronog. e Histog.'!K98>0,'Cronog. e Histog.'!K98,#N/A) -> 0.1 | C7: =IF('Cronog. e Histog.'!L98>0,'Cronog. e Histog.'!L98,#N/A) -> 0.2 | D7: =IF('Cronog. e Histog.'!M98>0,'Cronog. e Histog.'!M98,#N/A) -> 0.3 | E7: =IF('Cronog. e Histog.'!N98>0,'Cronog. e Histog.'!N98,#N/A) -> 0.4 | F7: =IF('Cronog. e Histog.'!O98>0,'Cronog. e Histog.'!O98,#N/A) -> 0.5 | G7: =IF('Cronog. e Histog.'!P98>0,'Cronog. e Histog.'!P98,#N/A) -> 0.6 | H7: =IF('Cronog. e Histog.'!Q98>0,'Cronog. e Histog.'!Q98,#N/A) -> 0.7 | I7: =IF('Cronog. e Histog.'!R98>0,'Cronog. e Histog.'!R98,#N/A) -> 0.8 | ... BI7: =IF('Cronog. e Histog.'!BR98>0,'Cronog. e Histog.'!BR98,#N/A) -> #N/A
B25: Histograma de Mão de Obra Direta
B26: 1 | C26: 2 | D26: 3 | E26: 4 | F26: 5 | G26: 6 | H26: 7 | I26: 8 | J26: 9 | K26: 10 | L26: 11 | M26: 12 | N26: 13 | O26: 14 | P26: 15 | Q26: 16 | R26: 17 | S26: 18 | T26: 19 | U26: 20 | V26: 21 | W26: 22 | X26: 23 | Y26: 24 | Z26: 25 | AA26: 26 | AB26: 27 | AC26: 28 | AD26: 29 | AE26: 30 | AF26: 31 | AG26: 32 | AH26: 33 | AI26: 34 | AJ26: 35 | AK26: 36 | AL26: 37 | AM26: 38 | AN26: 39 | AO26: 40 | AP26: 41 | AQ26: 42 | AR26: 43 | AS26: 44 | AT26: 45 | AU26: 46 | AV26: 47 | AW26: 48 | AX26: 49 | AY26: 50 | AZ26: 51 | BA26: 52 | BB26: 53 | BC26: 54 | BD26: 55 | BE26: 56 | BF26: 57 | BG26: 58 | BH26: 59 | BI26: 60
B27: =B69 -> 8.54 | C27: =C69 -> 8.54 | D27: =D69 -> 8.54 | E27: =E69 -> 8.54 | F27: =F69 -> 8.54 | G27: =G69 -> 8.54 | H27: =H69 -> 8.54 | I27: =I69 -> 8.54 | ... BI27: =BI69 -> #N/A
B46: Histograma de Mão de Obra Indireta
B47: 1 | C47: 2 | D47: 3 | E47: 4 | F47: 5 | G47: 6 | H47: 7 | I47: 8 | J47: 9 | K47: 10 | L47: 11 | M47: 12 | N47: 13 | O47: 14 | P47: 15 | Q47: 16 | R47: 17 | S47: 18 | T47: 19 | U47: 20 | V47: 21 | W47: 22 | X47: 23 | Y47: 24 | Z47: 25 | AA47: 26 | AB47: 27 | AC47: 28 | AD47: 29 | AE47: 30 | AF47: 31 | AG47: 32 | AH47: 33 | AI47: 34 | AJ47: 35 | AK47: 36 | AL47: 37 | AM47: 38 | AN47: 39 | AO47: 40 | AP47: 41 | AQ47: 42 | AR47: 43 | AS47: 44 | AT47: 45 | AU47: 46 | AV47: 47 | AW47: 48 | AX47: 49 | AY47: 50 | AZ47: 51 | BA47: 52 | BB47: 53 | BC47: 54 | BD47: 55 | BE47: 56 | BF47: 57 | BG47: 58 | BH47: 59 | BI47: 60
B48: =B70 -> 0.08 | C48: =C70 -> 0.08 | D48: =D70 -> 0.08 | E48: =E70 -> 0.08 | F48: =F70 -> 0.08 | G48: =G70 -> 0.08 | H48: =H70 -> 0.08 | I48: =I70 -> 0.08 | ... BI48: =BI70 -> #N/A
B67: Histograma de Mão de Obra
B68: 1 | C68: 2 | D68: 3 | E68: 4 | F68: 5 | G68: 6 | H68: 7 | I68: 8 | J68: 9 | K68: 10 | L68: 11 | M68: 12 | N68: 13 | O68: 14 | P68: 15 | Q68: 16 | R68: 17 | S68: 18 | T68: 19 | U68: 20 | V68: 21 | W68: 22 | X68: 23 | Y68: 24 | Z68: 25 | AA68: 26 | AB68: 27 | AC68: 28 | AD68: 29 | AE68: 30 | AF68: 31 | AG68: 32 | AH68: 33 | AI68: 34 | AJ68: 35 | AK68: 36 | AL68: 37 | AM68: 38 | AN68: 39 | AO68: 40 | AP68: 41 | AQ68: 42 | AR68: 43 | AS68: 44 | AT68: 45 | AU68: 46 | AV68: 47 | AW68: 48 | AX68: 49 | AY68: 50 | AZ68: 51 | BA68: 52 | BB68: 53 | BC68: 54 | BD68: 55 | BE68: 56 | BF68: 57 | BG68: 58 | BH68: 59 | BI68: 60
B69: =IF('Cronog. e Histog.'!K858+'Cronog. e Histog.'!K859>0,'Cronog. e Histog.'!K858+'Cronog. e Histog.'!K858,#N/A) -> 8.54 | C69: =IF('Cronog. e Histog.'!L858+'Cronog. e Histog.'!L859>0,'Cronog. e Histog.'!L858+'Cronog. e Histog.'!L858,#N/A) -> 8.54 | D69: =IF('Cronog. e Histog.'!M858+'Cronog. e Histog.'!M859>0,'Cronog. e Histog.'!M858+'Cronog. e Histog.'!M858,#N/A) -> 8.54 | E69: =IF('Cronog. e Histog.'!N858+'Cronog. e Histog.'!N859>0,'Cronog. e Histog.'!N858+'Cronog. e Histog.'!N858,#N/A) -> 8.54 | F69: =IF('Cronog. e Histog.'!O858+'Cronog. e Histog.'!O859>0,'Cronog. e Histog.'!O858+'Cronog. e Histog.'!O858,#N/A) -> 8.54 | G69: =IF('Cronog. e Histog.'!P858+'Cronog. e Histog.'!P859>0,'Cronog. e Histog.'!P858+'Cronog. e Histog.'!P858,#N/A) -> 8.54 | H69: =IF('Cronog. e Histog.'!Q858+'Cronog. e Histog.'!Q859>0,'Cronog. e Histog.'!Q858+'Cronog. e Histog.'!Q858,#N/A) -> 8.54 | I69: =IF('Cronog. e Histog.'!R858+'Cronog. e Histog.'!R859>0,'Cronog. e Histog.'!R858+'Cronog. e Histog.'!R858,#N/A) -> 8.54 | ... BI69: =IF('Cronog. e Histog.'!BR858+'Cronog. e Histog.'!BR859>0,'Cronog. e Histog.'!BR858+'Cronog. e Histog.'!BR858,#N/A) -> #N/A
B70: =IF('Cronog. e Histog.'!K860>0,'Cronog. e Histog.'!K860,#N/A) -> 0.08 | C70: =IF('Cronog. e Histog.'!L860>0,'Cronog. e Histog.'!L860,#N/A) -> 0.08 | D70: =IF('Cronog. e Histog.'!M860>0,'Cronog. e Histog.'!M860,#N/A) -> 0.08 | E70: =IF('Cronog. e Histog.'!N860>0,'Cronog. e Histog.'!N860,#N/A) -> 0.08 | F70: =IF('Cronog. e Histog.'!O860>0,'Cronog. e Histog.'!O860,#N/A) -> 0.08 | G70: =IF('Cronog. e Histog.'!P860>0,'Cronog. e Histog.'!P860,#N/A) -> 0.08 | H70: =IF('Cronog. e Histog.'!Q860>0,'Cronog. e Histog.'!Q860,#N/A) -> 0.08 | I70: =IF('Cronog. e Histog.'!R860>0,'Cronog. e Histog.'!R860,#N/A) -> 0.08 | ... BI70: =IF('Cronog. e Histog.'!BR860>0,'Cronog. e Histog.'!BR860,#N/A) -> #N/A
B71: ='Cronog. e Histog.'!K861 -> 4.35 | C71: ='Cronog. e Histog.'!L861 -> 4.35 | D71: ='Cronog. e Histog.'!M861 -> 4.35 | E71: ='Cronog. e Histog.'!N861 -> 4.35 | F71: ='Cronog. e Histog.'!O861 -> 4.35 | G71: ='Cronog. e Histog.'!P861 -> 4.35 | H71: ='Cronog. e Histog.'!Q861 -> 4.35 | I71: ='Cronog. e Histog.'!R861 -> 4.35 | ... BI71: ='Cronog. e Histog.'!BR861 -> 0
B90: Gráficos de Custos e Resultados
B92: Custos
B93: =Dashboard!K3 -> Mão de Obra Indireta | C93: =IF(Dashboard!L3>0,Dashboard!L3,#N/A) -> 17160
B94: =Dashboard!K5 -> Mão de Obra Direta (rotina) | C94: =IF(Dashboard!L5>0,Dashboard!L5,#N/A) -> #N/A
B95: =Dashboard!K7 -> Encargos Sociais - Horistas | C95: =IF(Dashboard!L7>0,Dashboard!L7,#N/A) -> #N/A
B96: =Dashboard!K8 -> Mobilização/ Integração de Mão de Obra | C96: =IF(Dashboard!L8>0,Dashboard!L8,#N/A) -> #N/A
B97: =Dashboard!K9 -> Desmobilização de Mão de Obra | C97: =IF(Dashboard!L9>0,Dashboard!L9,#N/A) -> #N/A
B98: =Dashboard!K10 -> Canteiro de Obras, Infraestrutura de Apoio e Alojamento | C98: =IF(Dashboard!L10>0,Dashboard!L10,#N/A) -> #N/A
B99: =Dashboard!K11 -> Benefícios | C99: =IF(Dashboard!L11>0,Dashboard!L11,#N/A) -> 62455.76
B100: =Dashboard!K12 -> Exames Médicos e Gestão da Saúde Ocupacional | C100: =IF(Dashboard!L12>0,Dashboard!L12,#N/A) -> 3915
B101: =Dashboard!K13 -> EPI's - Equipamentos de Proteção Individual | C101: =IF(Dashboard!L13>0,Dashboard!L13,#N/A) -> 14142.384
B102: =Dashboard!K14 -> EPC's - Equipamentos de Proteção Coletiva | C102: =IF(Dashboard!L14>0,Dashboard!L14,#N/A) -> 2464.5833
B103: =Dashboard!K15 -> Treinamentos | C103: =IF(Dashboard!L15>0,Dashboard!L15,#N/A) -> #N/A
B104: =Dashboard!K16 -> Viagens e Hospedagem | C104: =IF(Dashboard!L16>0,Dashboard!L16,#N/A) -> 87000
B105: =Dashboard!K17 -> Equipamentos e Ferramentas | C105: =IF(Dashboard!L17>0,Dashboard!L17,#N/A) -> 2000
B106: =Dashboard!K18 -> Equipamentos de Informática e Softwares | C106: =IF(Dashboard!L18>0,Dashboard!L18,#N/A) -> 39989.467
B107: =Dashboard!K19 -> Veículos leves e Fretamento | C107: =IF(Dashboard!L19>0,Dashboard!L19,#N/A) -> #N/A
B108: =Dashboard!K21 -> Materiais de Consumo | C108: =IF(Dashboard!L21>0,Dashboard!L21,#N/A) -> #N/A
B109: =Dashboard!K22 -> Materiais de Aplicação Gerais | C109: =IF(Dashboard!L22>0,Dashboard!L22,#N/A) -> #N/A
B110: =Dashboard!K23 -> Serviços Terceirizados | C110: =IF(Dashboard!L23>0,Dashboard!L23,#N/A) -> 3929.4
B111: =Dashboard!K24 -> Locações | C111: =IF(Dashboard!L24>0,Dashboard!L24,#N/A) -> #N/A
B112: =Dashboard!K25 -> Mobilização e Desmobilização de Recursos | C112: =IF(Dashboard!L25>0,Dashboard!L25,#N/A) -> 850
B113: =Dashboard!K26 -> Riscos e Contingências | C113: =IF(Dashboard!L26>0,Dashboard!L26,#N/A) -> #N/A
B114: =Dashboard!K27 -> Outros Custos | C114: =IF(Dashboard!L27>0,Dashboard!L27,#N/A) -> #N/A
...

Sheet HISTOGRAMA
D2: HISTOGRAMA
D3: TERRAPLENAGEM | G3: EXECUÇÃO DA OBRA
D4: PRÉ-OBRA
D5: 1 | E5: 2 | F5: 1 | G5: 2 | H5: 3 | I5: 4 | J5: 5 | K5: 6 | L5: 7 | M5: 11 | N5: 12 | O5: 13 | P5: 14 | Q5: 15 | R5: 16 | S5: 17 | T5: 18
B6: EQUIPE | C6: Prazo | D6: M1 | E6: M2 | F6: M3 | G6: M4 | H6: M5 | I6: M6 | J6: M7 | K6: M8 | L6: M9 | M6: M10 | N6: M11 | O6: M12 | P6: M13 | Q6: M14 | R6: M15 | S6: M16 | T6: M17
A7: CÓD | B7: GERENCIAMENTO DE OBRA
A8: Equipe_01 | B8: =IFERROR(INDEX(Tarefas!F:F,MATCH(A8,Tarefas!N:N,0)),"") -> Coordenador de Obras - Full time 100% | C8: =COUNTA(D8:T8) -> 10 | D8: 1 | E8: 1 | F8: 1 | G8: 1 | H8: 1 | I8: 1 | J8: 1 | K8: 1 | L8: 1 | M8: 1
A9: Equipe_02 | B9: =IFERROR(INDEX(Tarefas!F:F,MATCH(A9,Tarefas!N:N,0)),"") -> Engenheiro Pl. de Planejamento, Qualidade e Custos ( Supervisor) - Full time | C9: =COUNTA(D9:T9) -> 7 | G9: 1 | H9: 1 | I9: 1 | J9: 1 | K9: 1 | L9: 1 | M9: 1
A10: Equipe_10 | B10: =IFERROR(INDEX(Tarefas!F:F,MATCH(A10,Tarefas!N:N,0)),"") -> Engenheiro Pl. de Planejamento, Qualidade e Custos ( Supervisor) - Full time | C10: =COUNTA(D10:T10) -> 3 | D10: 0.2 | E10: 0.2 | F10: 0.2
A11: Equipe_03 | B11: =IFERROR(INDEX(Tarefas!F:F,MATCH(A11,Tarefas!N:N,0)),"") -> Engenheiro Jr. Qualidade ( Supervisor) - Instalações 25% | C11: =COUNTA(D11:T11) -> 5 | I11: 0.25 | J11: 0.25 | K11: 0.25 | L11: 0.25 | M11: 0.25
A12: Equipe_04 | B12: =IFERROR(INDEX(Tarefas!F:F,MATCH(A12,Tarefas!N:N,0)),"") -> Analista de Custos - An. Sr. 50% | C12: =COUNTA(D12:T12) -> 6 | H12: 0.5 | I12: 0.5 | J12: 0.5 | K12: 0.5 | L12: 0.5 | M12: 0.5
A13: Equipe_05 | B13: =IFERROR(INDEX(Tarefas!F:F,MATCH(A13,Tarefas!N:N,0)),"") -> Arquiteto Pl. ( Gestão de projetos) - Remoto ( Supervisor) - 100% | C13: =COUNTA(D13:T13) -> 6 | F13: 1 | G13: 1 | H13: 1 | I13: 1 | J13: 1 | K13: 1
A14: Equipe_20 | B14: =IFERROR(INDEX(Tarefas!F:F,MATCH(A14,Tarefas!N:N,0)),"") -> Arquiteto Pl. ( Gestão de projetos) - Remoto ( Supervisor) - 50% | C14: =COUNTA(D14:T14) -> 2 | L14: 0.5 | M14: 0.5
A15: Equipe_06 | B15: =IFERROR(INDEX(Tarefas!F:F,MATCH(A15,Tarefas!N:N,0)),"") -> Técnico de Segurança | C15: =COUNTA(D15:T15) -> 10 | D15: 1 | E15: 1 | F15: 1 | G15: 1 | H15: 1 | I15: 1 | J15: 1 | K15: 1 | L15: 1 | M15: 1
A16: Equipe_07 | B16: =IFERROR(INDEX(Tarefas!F:F,MATCH(A16,Tarefas!N:N,0)),"") -> Gerrente de Obras - 5% - Considerado equipe diluida nas linhas com 10 meses | C16: =COUNTA(D16:T16) -> 10 | D16: =1*0 -> 0 | E16: =1*0 -> 0 | F16: =1*0 -> 0 | G16: =1*0 -> 0 | H16: =1*0 -> 0 | I16: =1*0 -> 0 | J16: =1*0 -> 0 | K16: =1*0 -> 0 | ... M16: =1*0 -> 0
A17: Equipe_08 | B17: =IFERROR(INDEX(Tarefas!F:F,MATCH(A17,Tarefas!N:N,0)),"") -> Engenheiro de Segurança - 5% - Considerado equipe diluida nas linhas com 10 meses | C17: =COUNTA(D17:T17) -> 10 | D17: =1*0 -> 0 | E17: =1*0 -> 0 | F17: =1*0 -> 0 | G17: =1*0 -> 0 | H17: =1*0 -> 0 | I17: =1*0 -> 0 | J17: =1*0 -> 0 | K17: =1*0 -> 0 | ... M17: =1*0 -> 0
A18: Equipe_09 | B18: =IFERROR(INDEX(Tarefas!F:F,MATCH(A18,Tarefas!N:N,0)),"") -> Coordenador de Arquitetura - Excluso | C18: =COUNTA(D18:T18) -> 0
A19: Equipe_10 | B19: =IFERROR(INDEX(Tarefas!F:F,MATCH(A19,Tarefas!N:N,0)),"") -> Engenheiro Pl. de Planejamento, Qualidade e Custos ( Supervisor) - Full time | C19: =COUNTA(D19:T19) -> 0
A20: Equipe_11 | B20: =IFERROR(INDEX(Tarefas!F:F,MATCH(A20,Tarefas!N:N,0)),"") -> N/A | C20: =COUNTA(D20:T20) -> 0
A21: Equipe_12 | B21: =IFERROR(INDEX(Tarefas!F:F,MATCH(A21,Tarefas!N:N,0)),"") -> N/A | C21: =COUNTA(D21:T21) -> 0
A22: Equipe_13 | B22: =IFERROR(INDEX(Tarefas!F:F,MATCH(A22,Tarefas!N:N,0)),"") -> N/A | C22: =COUNTA(D22:T22) -> 0
A23: Equipe_14 | B23: =IFERROR(INDEX(Tarefas!F:F,MATCH(A23,Tarefas!N:N,0)),"") -> N/A | C23: =COUNTA(D23:T23) -> 0
A24: Equipe_15 | B24: =IFERROR(INDEX(Tarefas!F:F,MATCH(A24,Tarefas!N:N,0)),"") -> N/A | C24: =COUNTA(D24:T24) -> 0
A25: CÓD | B25: PRÉ-OBRA: APOIO À FASE DE CONCORRÊNCIA / SUPRIMENTOS
A26: Equipe_16 | B26: =IFERROR(INDEX(Tarefas!F:F,MATCH(A26,Tarefas!N:N,0)),"") -> Coordenador de Orçamentos - Part time - 50% mês | C26: =COUNTA(D26:T26) -> 2 | D26: 0.5 | E26: 0.5
A27: Equipe_17 | B27: =IFERROR(INDEX(Tarefas!F:F,MATCH(A27,Tarefas!N:N,0)),"") -> Arquiteto Pl. ( Gestão de projetos) - Remoto ( Supervisor) - 20% mês | C27: =COUNTA(D27:T27) -> 2 | D27: 0.2 | E27: 0.2
A28: Equipe_18 | B28: =IFERROR(INDEX(Tarefas!F:F,MATCH(A28,Tarefas!N:N,0)),"") -> Engenheiro Pl. de Planejamento, Qualidade e Custos ( Supervisor) - 10% - mês | C28: =COUNTA(D28:T28) -> 2 | D28: 0.1 | E28: 0.1
A29: Equipe_19 | B29: =IFERROR(INDEX(Tarefas!F:F,MATCH(A29,Tarefas!N:N,0)),"") -> Analista de Financeiro - An. Sr. 50% ( Análise financeira das empresas) | C29: =COUNTA(D29:T29) -> 1 | D29: 0.5
B30: TOTAL GERAL | D30: =SUM(D8:D29) -> 3.5 | E30: =SUM(E8:E29) -> 3 | F30: =SUM(F8:F29) -> 3.2 | G30: =SUM(G8:G29) -> 4 | H30: =SUM(H8:H29) -> 4.5 | I30: =SUM(I8:I29) -> 4.75 | J30: =SUM(J8:J29) -> 4.75 | K30: =SUM(K8:K29) -> 4.75 | ... T30: =SUM(T8:T29) -> 0
D32: CURVA DE DESEMBOLSO
D33: TERRAPLENAGEM | G33: EXECUÇÃO DA OBRA
D34: PRÉ-OBRA
D35: -3 | E35: -2 | F35: 1 | G35: 2 | H35: 3 | I35: 4 | J35: 5 | K35: 6 | L35: 7 | M35: 11 | N35: 12 | O35: 13 | P35: 14 | Q35: 12 | R35: 13 | S35: 14 | T35: 15
B36: EQUIPE (DEDICALÇAO INTEGRAL) | C36: VALOR TOTAL R$ | D36: M1 | E36: M2 | F36: M3 | G36: M4 | H36: M5 | I36: M6 | J36: M7 | K36: M8 | L36: M9 | M36: M10 | N36: M11 | O36: M12 | P36: M13 | Q36: M14 | R36: M15 | S36: M16 | T36: M17
A37: CÓD | B37: GERENCIAMENTO DE OBRA
A38: Equipe_01 | B38: =IFERROR(INDEX(Tarefas!F:F,MATCH(A38,Tarefas!N:N,0)),"") -> Coordenador de Obras - Full time 100% | C38: =ROUND(SUM(D38:T38),2) -> 509614.9 | D38: =ROUND(IF(D8>0,(INDEX(Tarefas!$AS:$AS,MATCH($A38,Tarefas!$N:$N,0))),0),2) -> 50961.49 | E38: =ROUND(IF(E8>0,(INDEX(Tarefas!$AS:$AS,MATCH($A38,Tarefas!$N:$N,0))),0),2) -> 50961.49 | F38: =ROUND(IF(F8>0,(INDEX(Tarefas!$AS:$AS,MATCH($A38,Tarefas!$N:$N,0))),0),2) -> 50961.49 | G38: =ROUND(IF(G8>0,(INDEX(Tarefas!$AS:$AS,MATCH($A38,Tarefas!$N:$N,0))),0),2) -> 50961.49 | H38: =ROUND(IF(H8>0,(INDEX(Tarefas!$AS:$AS,MATCH($A38,Tarefas!$N:$N,0))),0),2) -> 50961.49 | I38: =ROUND(IF(I8>0,(INDEX(Tarefas!$AS:$AS,MATCH($A38,Tarefas!$N:$N,0))),0),2) -> 50961.49 | J38: =ROUND(IF(J8>0,(INDEX(Tarefas!$AS:$AS,MATCH($A38,Tarefas!$N:$N,0))),0),2) -> 50961.49 | K38: =ROUND(IF(K8>0,(INDEX(Tarefas!$AS:$AS,MATCH($A38,Tarefas!$N:$N,0))),0),2) -> 50961.49 | ... T38: =ROUND(IF(T8>0,(INDEX(Tarefas!$AS:$AS,MATCH($A38,Tarefas!$N:$N,0))),0),2) -> 0
A39: Equipe_02 | B39: =IFERROR(INDEX(Tarefas!F:F,MATCH(A39,Tarefas!N:N,0)),"") -> Engenheiro Pl. de Planejamento, Qualidade e Custos ( Supervisor) - Full time | C39: =SUM(D39:T39) -> 278491.92 | D39: =ROUND(IF(D9>0,(INDEX(Tarefas!$AS:$AS,MATCH($A39,Tarefas!$N:$N,0))),0),2) -> 0 | E39: =ROUND(IF(E9>0,(INDEX(Tarefas!$AS:$AS,MATCH($A39,Tarefas!$N:$N,0))),0),2) -> 0 | F39: =ROUND(IF(F9>0,(INDEX(Tarefas!$AS:$AS,MATCH($A39,Tarefas!$N:$N,0))),0),2) -> 0 | G39: =ROUND(IF(G9>0,(INDEX(Tarefas!$AS:$AS,MATCH($A39,Tarefas!$N:$N,0))),0),2) -> 39784.56 | H39: =ROUND(IF(H9>0,(INDEX(Tarefas!$AS:$AS,MATCH($A39,Tarefas!$N:$N,0))),0),2) -> 39784.56 | I39: =ROUND(IF(I9>0,(INDEX(Tarefas!$AS:$AS,MATCH($A39,Tarefas!$N:$N,0))),0),2) -> 39784.56 | J39: =ROUND(IF(J9>0,(INDEX(Tarefas!$AS:$AS,MATCH($A39,Tarefas!$N:$N,0))),0),2) -> 39784.56 | K39: =ROUND(IF(K9>0,(INDEX(Tarefas!$AS:$AS,MATCH($A39,Tarefas!$N:$N,0))),0),2) -> 39784.56 | ... T39: =ROUND(IF(T9>0,(INDEX(Tarefas!$AS:$AS,MATCH($A39,Tarefas!$N:$N,0))),0),2) -> 0
A40: Equipe_10 | B40: =IFERROR(INDEX(Tarefas!F:F,MATCH(A40,Tarefas!N:N,0)),"") -> Engenheiro Pl. de Planejamento, Qualidade e Custos ( Supervisor) - Full time | C40: =SUM(D40:T40) -> 41747.04 | D40: =ROUND(IF(D10>0,(INDEX(Tarefas!$AS:$AS,MATCH($A40,Tarefas!$N:$N,0))),0),2) -> 13915.68 | E40: =ROUND(IF(E10>0,(INDEX(Tarefas!$AS:$AS,MATCH($A40,Tarefas!$N:$N,0))),0),2) -> 13915.68 | F40: =ROUND(IF(F10>0,(INDEX(Tarefas!$AS:$AS,MATCH($A40,Tarefas!$N:$N,0))),0),2) -> 13915.68 | G40: =ROUND(IF(G10>0,(INDEX(Tarefas!$AS:$AS,MATCH($A40,Tarefas!$N:$N,0))),0),2) -> 0 | H40: =ROUND(IF(H10>0,(INDEX(Tarefas!$AS:$AS,MATCH($A40,Tarefas!$N:$N,0))),0),2) -> 0 | I40: =ROUND(IF(I10>0,(INDEX(Tarefas!$AS:$AS,MATCH($A40,Tarefas!$N:$N,0))),0),2) -> 0 | J40: =ROUND(IF(J10>0,(INDEX(Tarefas!$AS:$AS,MATCH($A40,Tarefas!$N:$N,0))),0),2) -> 0 | K40: =ROUND(IF(K10>0,(INDEX(Tarefas!$AS:$AS,MATCH($A40,Tarefas!$N:$N,0))),0),2) -> 0 | ... T40: =ROUND(IF(T10>0,(INDEX(Tarefas!$AS:$AS,MATCH($A40,Tarefas!$N:$N,0))),0),2) -> 0
A41: Equipe_03 | B41: =IFERROR(INDEX(Tarefas!F:F,MATCH(A41,Tarefas!N:N,0)),"") -> Engenheiro Jr. Qualidade ( Supervisor) - Instalações 25% | C41: =SUM(D41:T41) -> 63875.8 | D41: =ROUND(IF(D11>0,(INDEX(Tarefas!$AS:$AS,MATCH($A41,Tarefas!$N:$N,0))),0),2) -> 0 | E41: =ROUND(IF(E11>0,(INDEX(Tarefas!$AS:$AS,MATCH($A41,Tarefas!$N:$N,0))),0),2) -> 0 | F41: =ROUND(IF(F11>0,(INDEX(Tarefas!$AS:$AS,MATCH($A41,Tarefas!$N:$N,0))),0),2) -> 0 | G41: =ROUND(IF(G11>0,(INDEX(Tarefas!$AS:$AS,MATCH($A41,Tarefas!$N:$N,0))),0),2) -> 0 | H41: =ROUND(IF(H11>0,(INDEX(Tarefas!$AS:$AS,MATCH($A41,Tarefas!$N:$N,0))),0),2) -> 0 | I41: =ROUND(IF(I11>0,(INDEX(Tarefas!$AS:$AS,MATCH($A41,Tarefas!$N:$N,0))),0),2) -> 12775.16 | J41: =ROUND(IF(J11>0,(INDEX(Tarefas!$AS:$AS,MATCH($A41,Tarefas!$N:$N,0))),0),2) -> 12775.16 | K41: =ROUND(IF(K11>0,(INDEX(Tarefas!$AS:$AS,MATCH($A41,Tarefas!$N:$N,0))),0),2) -> 12775.16 | ... T41: =ROUND(IF(T11>0,(INDEX(Tarefas!$AS:$AS,MATCH($A41,Tarefas!$N:$N,0))),0),2) -> 0
A42: Equipe_04 | B42: =IFERROR(INDEX(Tarefas!F:F,MATCH(A42,Tarefas!N:N,0)),"") -> Analista de Custos - An. Sr. 50% | C42: =SUM(D42:T42) -> 73229.46 | D42: =ROUND(IF(D12>0,(INDEX(Tarefas!$AS:$AS,MATCH($A42,Tarefas!$N:$N,0))),0),2) -> 0 | E42: =ROUND(IF(E12>0,(INDEX(Tarefas!$AS:$AS,MATCH($A42,Tarefas!$N:$N,0))),0),2) -> 0 | F42: =ROUND(IF(F12>0,(INDEX(Tarefas!$AS:$AS,MATCH($A42,Tarefas!$N:$N,0))),0),2) -> 0 | G42: =ROUND(IF(G12>0,(INDEX(Tarefas!$AS:$AS,MATCH($A42,Tarefas!$N:$N,0))),0),2) -> 0 | H42: =ROUND(IF(H12>0,(INDEX(Tarefas!$AS:$AS,MATCH($A42,Tarefas!$N:$N,0))),0),2) -> 12204.91 | I42: =ROUND(IF(I12>0,(INDEX(Tarefas!$AS:$AS,MATCH($A42,Tarefas!$N:$N,0))),0),2) -> 12204.91 | J42: =ROUND(IF(J12>0,(INDEX(Tarefas!$AS:$AS,MATCH($A42,Tarefas!$N:$N,0))),0),2) -> 12204.91 | K42: =ROUND(IF(K12>0,(INDEX(Tarefas!$AS:$AS,MATCH($A42,Tarefas!$N:$N,0))),0),2) -> 12204.91 | ... T42: =ROUND(IF(T12>0,(INDEX(Tarefas!$AS:$AS,MATCH($A42,Tarefas!$N:$N,0))),0),2) -> 0
...

Sheet Tarefas
E2: Item | F2: Descrição da Equipe | G2: Sigla | H2: Disciplina | L2: Improd. por Equipe | O2: HH Total por equipe | S2: Custo Total por Equipe | T2: Custo da Hora por Disciplina | BT2: =HYPERLINK("#GER",BU2) -> GER. (OBRA/PROJ) | BU2: ='Base Salarial'!G5 -> GER. (OBRA/PROJ)
E3: 1 | F3: Equipe01 | G3: Equipe_01 | H3: PROJETO | L3: =IFERROR(_xlfn.XLOOKUP(G3,Improdutividade!$R$1:$AK$1,Improdutividade!$R$17:$AK$17),0) -> 0 | O3: =SUMIF($N$32:$N$54,G3,$O$32:$O$54) -> 1992.4667 | S3: =IFERROR(SUM(Precificação!U96:U115)/SUM(Precificação!$U$96:$U$533)*Precificação!$U$2,0) -> 308321.8 | T3: =IFERROR(S3/O3,0) -> 154.74377 | BT3: =HYPERLINK("#COORD.",BU3) -> COORD. | BU3: ='Base Salarial'!G7 -> COORD.
E4: 2 | F4: Equipe02 | G4: Equipe_02 | H4: PERMITS | L4: =IFERROR(_xlfn.XLOOKUP(G4,Improdutividade!$R$1:$AK$1,Improdutividade!$R$17:$AK$17),0) -> 0 | O4: =SUMIF($N$32:$N$54,G4,$O$32:$O$54) -> 1394.7267 | S4: =IFERROR(SUM(Precificação!U118:U137)/SUM(Precificação!$U$96:$U$533)*Precificação!$U$2,0) -> 162349.22 | T4: =IFERROR(S4/O4,0) -> 116.40218 | BT4: =HYPERLINK("#SUP.ESP",BU4) -> SUP.-ESP | BU4: ='Base Salarial'!G8 -> SUP.-ESP
E5: 3 | F5: Equipe03 | G5: Equipe_03 | H5: GERENCIMENTO | L5: =IFERROR(_xlfn.XLOOKUP(G5,Improdutividade!$R$1:$AK$1,Improdutividade!$R$17:$AK$17),0) -> 0 | O5: =SUMIF($N$32:$N$54,G5,$O$32:$O$54) -> 242 | S5: =IFERROR(SUM(Precificação!U140:U159)/SUM(Precificação!$U$96:$U$533)*Precificação!$U$2,0) -> 28659.126 | T5: =IFERROR(S5/O5,0) -> 118.42614 | BT5: =HYPERLINK("#ENGARQSR",BU5) -> ENG/ARQ SR. | BU5: ='Base Salarial'!G9 -> ENG/ARQ SR.
E6: 4 | F6: Equipe04 | G6: Equipe_04 | H6: SUPRIMENTOS | L6: =IFERROR(_xlfn.XLOOKUP(G6,Improdutividade!$R$1:$AK$1,Improdutividade!$R$17:$AK$17),0) -> 0 | O6: =SUMIF($N$32:$N$54,G6,$O$32:$O$54) -> 580.8 | S6: =IFERROR(SUM(Precificação!U162:U181)/SUM(Precificação!$U$96:$U$533)*Precificação!$U$2,0) -> 35052.315 | T6: =IFERROR(S6/O6,0) -> 60.351783 | BT6: =HYPERLINK("#ENGARQPL",BU6) -> ENG/ARQ PL. | BU6: ='Base Salarial'!G10 -> ENG/ARQ PL.
E7: 5 | F7: Equipe05 | G7: Equipe_05 | H7: ORÇAMENTOS | L7: =IFERROR(_xlfn.XLOOKUP(G7,Improdutividade!$R$1:$AK$1,Improdutividade!$R$17:$AK$17),0) -> 0 | O7: =SUMIF($N$32:$N$54,G7,$O$32:$O$54) -> 1176.12 | S7: =IFERROR(SUM(Precificação!U184:U203)/SUM(Precificação!$U$96:$U$533)*Precificação!$U$2,0) -> 134792.37 | T7: =IFERROR(S7/O7,0) -> 114.60767 | BT7: =HYPERLINK("#ENGARQJR",BU7) -> ENG/ARQ JR. | BU7: ='Base Salarial'!G11 -> ENG/ARQ JR.
E8: 6 | F8: Equipe06 | G8: Equipe_06 | L8: =IFERROR(_xlfn.XLOOKUP(G8,Improdutividade!$R$1:$AK$1,Improdutividade!$R$17:$AK$17),0) -> 0 | O8: =SUMIF($N$32:$N$54,G8,$O$32:$O$54) -> 2089.2667 | S8: =IFERROR(SUM(Precificação!U206:U225)/SUM(Precificação!$U$96:$U$533)*Precificação!$U$2,0) -> 115124.65 | T8: =IFERROR(S8/O8,0) -> 55.102901 | BT8: =HYPERLINK("#ANSR.ENGARQ",BU8) -> AN SR. ENG/ARQ | BU8: ='Base Salarial'!G12 -> AN SR. ENG/ARQ
E9: 7 | F9: Equipe07 | G9: Equipe_07 | L9: =IFERROR(_xlfn.XLOOKUP(G9,Improdutividade!$R$1:$AK$1,Improdutividade!$R$17:$AK$17),0) -> 0 | O9: =SUMIF($N$32:$N$54,G9,$O$32:$O$54) -> 0 | S9: =IFERROR(SUM(Precificação!U228:U247)/SUM(Precificação!$U$96:$U$533)*Precificação!$U$2,0) -> 0 | T9: =IFERROR(S9/O9,0) -> 0 | BT9: =HYPERLINK("#ANPL.ENGARQ",BU9) -> AN PL. ENG/ARQ | BU9: ='Base Salarial'!G13 -> AN PL. ENG/ARQ
E10: 8 | F10: Equipe08 | G10: Equipe_08 | L10: =IFERROR(_xlfn.XLOOKUP(G10,Improdutividade!$R$1:$AK$1,Improdutividade!$R$17:$AK$17),0) -> 0 | O10: =SUMIF($N$32:$N$54,G10,$O$32:$O$54) -> 0 | S10: =IFERROR(SUM(Precificação!U250:U269)/SUM(Precificação!$U$96:$U$533)*Precificação!$U$2,0) -> 0 | T10: =IFERROR(S10/O10,0) -> 0 | BT10: =HYPERLINK("#ANJR.ENGARQ",BU10) -> AN JR. ENG/ARQ | BU10: ='Base Salarial'!G14 -> AN JR. ENG/ARQ
E11: 9 | F11: Equipe09 | G11: Equipe_09 | L11: =IFERROR(_xlfn.XLOOKUP(G11,Improdutividade!$R$1:$AK$1,Improdutividade!$R$17:$AK$17),0) -> 0 | O11: =SUMIF($N$32:$N$54,G11,$O$32:$O$54) -> 0 | S11: =IFERROR(SUM(Precificação!U272:U291)/SUM(Precificação!$U$96:$U$533)*Precificação!$U$2,0) -> 0 | T11: =IFERROR(S11/O11,0) -> 0 | BT11: =HYPERLINK("#ANSR.ADMCRP",BU11) -> AN SR. ADM/CRP | BU11: ='Base Salarial'!G15 -> AN SR. ADM/CRP
E12: 10 | F12: Equipe10 | G12: Equipe_10 | L12: =IFERROR(_xlfn.XLOOKUP(G12,Improdutividade!$R$1:$AK$1,Improdutividade!$R$17:$AK$17),0) -> 0 | O12: =SUMIF($N$32:$N$54,G12,$O$32:$O$54) -> 133.1 | S12: =IFERROR(SUM(Precificação!U294:U313)/SUM(Precificação!$U$96:$U$533)*Precificação!$U$2,0) -> 16534.111 | T12: =IFERROR(S12/O12,0) -> 124.22322 | BT12: =HYPERLINK("#ANPL.ADMCRP",BU12) -> AN PL. ADM/CRP | BU12: ='Base Salarial'!G16 -> AN PL. ADM/CRP
E13: 11 | F13: Equipe11 | G13: Equipe_11 | L13: =IFERROR(_xlfn.XLOOKUP(G13,Improdutividade!$R$1:$AK$1,Improdutividade!$R$17:$AK$17),0) -> 0 | O13: =SUMIF($N$32:$N$54,G13,$O$32:$O$54) -> 0 | S13: =IFERROR(SUM(Precificação!U316:U335)/SUM(Precificação!$U$96:$U$533)*Precificação!$U$2,0) -> 0 | T13: =IFERROR(S13/O13,0) -> 0 | BT13: =HYPERLINK("#ANJR.ADMCRP",BU13) -> AN JR. ADM/CRP | BU13: ='Base Salarial'!G17 -> AN JR. ADM/CRP
E14: 12 | F14: Equipe12 | G14: Equipe_12 | L14: =IFERROR(_xlfn.XLOOKUP(G14,Improdutividade!$R$1:$AK$1,Improdutividade!$R$17:$AK$17),0) -> 0 | O14: =SUMIF($N$32:$N$54,G14,$O$32:$O$54) -> 0 | S14: =IFERROR(SUM(Precificação!U338:U357)/SUM(Precificação!$U$96:$U$533)*Precificação!$U$2,0) -> 0 | T14: =IFERROR(S14/O14,0) -> 0 | BT14: =HYPERLINK("#TECIII",BU14) -> TEC III | BU14: ='Base Salarial'!G18 -> TEC III
E15: 13 | F15: Equipe13 | G15: Equipe_13 | L15: =IFERROR(_xlfn.XLOOKUP(G15,Improdutividade!$R$1:$AK$1,Improdutividade!$R$17:$AK$17),0) -> 0 | O15: =SUMIF($N$32:$N$54,G15,$O$32:$O$54) -> 0 | S15: =IFERROR(SUM(Precificação!U360:U379)/SUM(Precificação!$U$96:$U$533)*Precificação!$U$2,0) -> 0 | T15: =IFERROR(S15/O15,0) -> 0 | BT15: =HYPERLINK("#TECII",BU15) -> TEC II | BU15: ='Base Salarial'!G19 -> TEC II
E16: 14 | F16: Equipe14 | G16: Equipe_14 | L16: =IFERROR(_xlfn.XLOOKUP(G16,Improdutividade!$R$1:$AK$1,Improdutividade!$R$17:$AK$17),0) -> 0 | O16: =SUMIF($N$32:$N$54,G16,$O$32:$O$54) -> 0 | S16: =IFERROR(SUM(Precificação!U382:U401)/SUM(Precificação!$U$96:$U$533)*Precificação!$U$2,0) -> 0 | T16: =IFERROR(S16/O16,0) -> 0 | BT16: =HYPERLINK("#TECI",BU16) -> TEC I | BU16: ='Base Salarial'!G20 -> TEC I
E17: 15 | F17: Equipe15 | G17: Equipe_15 | L17: =IFERROR(_xlfn.XLOOKUP(G17,Improdutividade!$R$1:$AK$1,Improdutividade!$R$17:$AK$17),0) -> 0 | O17: =SUMIF($N$32:$N$54,G17,$O$32:$O$54) -> 0 | S17: =IFERROR(SUM(Precificação!U404:U423)/SUM(Precificação!$U$96:$U$533)*Precificação!$U$2,0) -> 0 | T17: =IFERROR(S17/O17,0) -> 0 | BT17: =HYPERLINK("#AUXTEC",BU17) -> AUX TEC | BU17: ='Base Salarial'!G21 -> AUX TEC
E18: 16 | F18: Equipe16 | G18: Equipe_16 | L18: =IFERROR(_xlfn.XLOOKUP(G18,Improdutividade!$R$1:$AK$1,Improdutividade!$R$17:$AK$17),0) -> 0 | O18: =SUMIF($N$32:$N$54,G18,$O$32:$O$54) -> 193.6 | S18: =IFERROR(SUM(Precificação!U426:U445)/SUM(Precificação!$U$96:$U$533)*Precificação!$U$2,0) -> 29918.868 | T18: =IFERROR(S18/O18,0) -> 154.53961 | BT18: =HYPERLINK("#AUXADM",BU18) -> AUX ADM | BU18: ='Base Salarial'!G22 -> AUX ADM
E19: 17 | F19: Equipe17 | G19: Equipe_17 | L19: =IFERROR(_xlfn.XLOOKUP(G19,Improdutividade!$R$1:$AK$1,Improdutividade!$R$17:$AK$17),0) -> 0 | O19: =SUMIF($N$32:$N$54,G19,$O$32:$O$54) -> 77.44 | S19: =IFERROR(SUM(Precificação!U448:U467)/SUM(Precificação!$U$96:$U$533)*Precificação!$U$2,0) -> 8818.1926 | T19: =IFERROR(S19/O19,0) -> 113.87129 | BT19: =HYPERLINK("#EST",BU19) -> EST_III | BU19: ='Base Salarial'!G25 -> EST_III
E20: 18 | F20: Equipe18 | G20: Equipe_18 | L20: =IFERROR(_xlfn.XLOOKUP(G20,Improdutividade!$R$1:$AK$1,Improdutividade!$R$17:$AK$17),0) -> 0 | O20: =SUMIF($N$32:$N$54,G20,$O$32:$O$54) -> 38.72 | S20: =IFERROR(SUM(Precificação!U470:U489)/SUM(Precificação!$U$96:$U$533)*Precificação!$U$2,0) -> 4409.0963 | T20: =IFERROR(S20/O20,0) -> 113.87129
E21: 19 | F21: Equipe19 | G21: Equipe_19 | L21: =IFERROR(_xlfn.XLOOKUP(G21,Improdutividade!$R$1:$AK$1,Improdutividade!$R$17:$AK$17),0) -> 0 | O21: =SUMIF($N$32:$N$54,G21,$O$32:$O$54) -> 96.8 | S21: =IFERROR(SUM(Precificação!U492:U511)/SUM(Precificação!$U$96:$U$533)*Precificação!$U$2,0) -> 5842.0526 | T21: =IFERROR(S21/O21,0) -> 60.351783
E22: 20 | F22: Equipe20 | G22: Equipe_20 | L22: =IFERROR(_xlfn.XLOOKUP(G22,Improdutividade!$R$1:$AK$1,Improdutividade!$R$17:$AK$17),0) -> 0 | O22: =SUMIF($N$32:$N$54,G22,$O$32:$O$54) -> 198.44 | S22: =IFERROR(SUM(Precificação!U514:U533)/SUM(Precificação!$U$96:$U$533)*Precificação!$U$2,0) -> 24250.03 | T22: =IFERROR(S22/O22,0) -> 122.20333
O23: =SUM(O3:O22) -> 8213.48 | S23: =SUM(S3:S22) -> 874071.84 | T23: =IFERROR(S23/O23,0) -> 106.41918
E25: Descrição das Atividades/ Itens | J25: Produtividade | K25: Produtividade | Q25: Valor de Serviços | R25: Valores de Serviços Próprios | W25: Suprimentos | X25: Valores de Materiais | AP25: Preço de Venda | AQ25: Preço de Venda | AY25: Impostos | AZ25: Impostos Totais | BO25: Memória de Cálculo | BP25: Gerentes e Coordenadores | BT25: =BO25 -> Memória de Cálculo | BY25: Supervisores e Especialistas | CD25: Engenheiros e Arquitetos | CQ25: Analistas Engenheiros e Arquitetos | DD25: Analistas Administrativos | DQ25: Técnicos | ED25: Auxiliares e Estágiários | EY25: Serviços Fornecedores | FO25: Memória de Cálculo - PPU | FP25: =FO25 -> Memória de Cálculo - PPU
F27: =F28*0.05 -> 12000000 | O27: HH Total | S27: Custo Total | U27: Venda Total | AC27: Custo Total | AN27: Venda Total | AS27: =AT28/F28 -> 0.0064013158 | AT27: Venda Total | AZ27: Impostos Serviços | BE27: Impostos de Materiais
F28: =60000*4000 -> 240000000 | O28: =SUM(O32:O54) -> 8213.48 | S28: =SUM(S32:S54) -> 874071.84 | U28: =SUM(U32:U54) -> 1278817.6 | AC28: =SUM(AC32:AC54) -> 176000 | AN28: =SUM(AN32:AN54) -> 257498.17 | AS28: =AT28/Dashboard!D13 -> 153631.58 | AT28: =SUM(AT32:AT54) -> 1536315.8 | AZ28: =SUM(AZ32:AZ54) -> 110617.72 | BA28: =SUM(BA32:BA54) -> 46676.843 | BB28: =SUM(BB32:BB54) -> 0 | BC28: =SUM(BC32:BC54) -> 63940.881 | BE28: =SUM(BE32:BE54) -> 22273.592 | BF28: =SUM(BF32:BF54) -> 0 | BG28: =SUM(BG32:BG54) -> 9398.6832 | BH28: =SUM(BH32:BH54) -> 0 | BI28: =SUM(BI32:BI54) -> 12874.909 | BJ28: =SUM(BJ32:BJ54) -> 0 | BK28: =SUM(BK32:BK54) -> 0 | BT28: 1 | BX28: 2 | CC28: 3 | CH28: 4 | CL28: 5 | CP28: 6 | CU28: 7 | CY28: 8 | DC28: 9 | DH28: 10 | DL28: 11 | DP28: 12 | DU28: 13 | DY28: 14 | EC28: 15 | EH28: 16 | EL28: 17 | EP28: 18 | ET28: 19 | EX28: 20 | EZ28: 21 | FA28: 22 | FB28: 23 | FC28: 24 | FD28: 25 | FE28: 26 | FF28: 27 | FG28: 28 | FH28: 29 | FI28: 30 | FJ28: 31 | FK28: 32
BR29: =#REF!/#REF! -> #REF! | BT29: PJ | BX29: PJ | CC29: Mensalista | CH29: PJ | CL29: PJ | CP29: PJ | CU29: Mensalista | CY29: Mensalista | DC29: Mensalista | DH29: Mensalista | DL29: Mensalista | DP29: Mensalista | DU29: Mensalista | DY29: Mensalista | EC29: Mensalista | EH29: Mensalista | EL29: Mensalista | EP29: PJ | ET29: PJ | EX29: PJ
B30: De | C30: Para | E30: Item | F30: Descrição | G30: Un. | H30: Qtd. | K30: Índice Puro | L30: Improdut. (%) | M30: Índice Improdutivo | N30: Equipe | O30: HH Total | R30: Custo Unit. | S30: Custo Total | T30: Venda Unit. | U30: Venda Total | X30: Custo Unit. | Y30: By-out | Z30: Fornecedor | AA30: Tipo de Fornecimento | AB30: Custo Unitário | AC30: Custo Total | AE30: ICMS - Origem | AF30: Taxa ICMS | AG30: PIS/ COFINS | AH30: CPRB | AI30: ISSQN | AJ30: IPI | AK30: Outros Imp. ou Taxas | AM30: Venda Unit. | AN30: Venda Total | AQ30: Venda Unitário Serviço | AR30: Venda Unitário Material | AS30: Venda Unitário Serviço + Material | AT30: Venda Total | AU30: % | AZ30: Impostos Serviços | BA30: PIS/COFINS | BB30: CPRB | BC30: ISSQN | BE30: Total Impostos de Materiais | BF30: ICMS | BG30: PIS/COFINS | BH30: CPRB | BI30: ISSQN | BJ30: IPI | BK30: Outros Impostos ou Taxas | BQ30: QT | BR30: D/M | BS30: h/D | BT30: GER. (OBRA/PROJ) | BU30: QT | BV30: D/M | BW30: H/D | BX30: =INDEX('Base Salarial'!$G$5:$G$25,MATCH(BX28,'Base Salarial'!$A$5:$A$25,0)) -> COORD. | BZ30: QT | CA30: D/M | CB30: H/D | CC30: =INDEX('Base Salarial'!$G$5:$G$25,MATCH(CC28,'Base Salarial'!$A$5:$A$25,0)) -> SUP.-ESP | CE30: QT | CF30: D/M | CG30: h/D | CH30: ENG/ARQ SR. | CI30: QT | CJ30: D/M | CK30: h/D | CL30: =INDEX('Base Salarial'!$G$5:$G$25,MATCH(CL28,'Base Salarial'!$A$5:$A$25,0)) -> ENG/ARQ PL. | CM30: QT | CN30: D/M | CO30: H/D | CP30: =INDEX('Base Salarial'!$G$5:$G$25,MATCH(CP28,'Base Salarial'!$A$5:$A$25,0)) -> ENG/ARQ JR. | CR30: QT | CS30: D/M | CT30: H/D | CU30: =INDEX('Base Salarial'!$G$5:$G$25,MATCH(CU28,'Base Salarial'!$A$5:$A$25,0)) -> AN SR. ENG/ARQ | CV30: QT | CW30: D/M | CX30: H/D | CY30: =INDEX('Base Salarial'!$G$5:$G$25,MATCH(CY28,'Base Salarial'!$A$5:$A$25,0)) -> AN PL. ENG/ARQ | CZ30: QT | DA30: D/M | DB30: H/D | DC30: =INDEX('Base Salarial'!$G$5:$G$25,MATCH(DC28,'Base Salarial'!$A$5:$A$25,0)) -> AN JR. ENG/ARQ | DE30: QT | DF30: D/M | DG30: H/D | DH30: =INDEX('Base Salarial'!$G$5:$G$25,MATCH(DH28,'Base Salarial'!$A$5:$A$25,0)) -> AN SR. ADM/CRP | DI30: QT | DJ30: D/M | DK30: H/D | DL30: =INDEX('Base Salarial'!$G$5:$G$25,MATCH(DL28,'Base Salarial'!$A$5:$A$25,0)) -> AN PL. ADM/CRP | DM30: QT | DN30: D/M | DO30: H/D | DP30: =INDEX('Base Salarial'!$G$5:$G$25,MATCH(DP28,'Base Salarial'!$A$5:$A$25,0)) -> AN JR. ADM/CRP | DR30: QT | DS30: D/M | DT30: H/D | DU30: =INDEX('Base Salarial'!$G$5:$G$25,MATCH(DU28,'Base Salarial'!$A$5:$A$25,0)) -> TEC III | DV30: QT | DW30: D/M | DX30: H/D | DY30: =INDEX('Base Salarial'!$G$5:$G$25,MATCH(DY28,'Base Salarial'!$A$5:$A$25,0)) -> TEC II | DZ30: QT | EA30: D/M | EB30: H/D | EC30: =INDEX('Base Salarial'!$G$5:$G$25,MATCH(EC28,'Base Salarial'!$A$5:$A$25,0)) -> TEC I | EE30: QT | EF30: D/M | EG30: H/D | EH30: =INDEX('Base Salarial'!$G$5:$G$25,MATCH(EH28,'Base Salarial'!$A$5:$A$25,0)) -> AUX TEC | EI30: QT | EJ30: D/M | EK30: H/D | EL30: =INDEX('Base Salarial'!$G$5:$G$25,MATCH(EL28,'Base Salarial'!$A$5:$A$25,0)) -> AUX ADM | EM30: QT | EN30: D/M | EO30: H/D | EP30: =INDEX('Base Salarial'!$G$5:$G$25,MATCH(EP28,'Base Salarial'!$A$5:$A$25,0)) -> EST | EQ30: QT | ER30: D/M | ES30: H/D | ET30: EST_II | EU30: QT | EV30: D/M | EW30: H/D | EX30: EST_III | EZ30: Ajuda de Custo
F31: GERENCIAMENTO DE OBRA
B32: =IFERROR(VLOOKUP(AE32,'Tabela ICMS'!$C$5:$D$32,2,0),"") | C32: =IFERROR(HLOOKUP(Dashboard!$F$9,'Tabela ICMS'!$E$3:$AF$4,2,0),"") -> 25 | E32: 1 | F32: Coordenador de Obras - Full time 100% | G32: mês | H32: =HISTOGRAMA!C8 -> 10 | K32: =SUMIFS(BT32:FK32,$BT$28:$FK$28,">=1",$BT$28:$FK$28,"<=18") -> 199.24667 | L32: =IFERROR(_xlfn.XLOOKUP(N32,$G$3:$G$22,$L$3:$L$22),0) -> 0 | M32: =K32*(1+L32) -> 199.24667 | N32: Equipe_01 | O32: =H32*M32 -> 1992.4667 | R32: =IFERROR(M32*VLOOKUP(N32,$G$3:$T$22,14,0),0) -> 30832.18 | S32: =H32*R32 -> 308321.8 | T32: =R32*(1+Dashboard!$D$35) -> 45109.262 | U32: =H32*T32 -> 451092.62 | X32: =SUMIFS(EZ32:FK32,$EZ$28:$FK$28,">=19",$EZ$28:$FK$28,"<=30") -> 4000 | AA32: Serviço | AB32: =X32*(1-Y32) -> 4000 | AC32: =H32*AB32 -> 40000 | AF32: {=IFERROR(INDEX('Tabela ICMS'!$E$5:$AF$32,Tarefas!B32,Tarefas!C32),0)} -> 0 | AG32: =IF(AA32="FD",(Dashboard!$D$43+Dashboard!$D$44),(Dashboard!$D$30+Dashboard!$D$31)) -> 0.0365 | AH32: =IF(AA32="FD",(Dashboard!$D$46),(Dashboard!$D$33)) -> 0 | AI32: =IF(AA32="FD",(Dashboard!$D$45),(Dashboard!$D$32)) -> 0.05 | AM32: =IF(AA32="FD",AB32*(1+Dashboard!$D$48),AB32*(1+Dashboard!$D$35)) -> 5852.2312 | AN32: =H32*AM32 -> 58522.312 | AQ32: =T32 -> 45109.262 | AR32: =AM32 -> 5852.2312 | AS32: =ROUND(T32+AM32,2) -> 50961.49 | AT32: =ROUND(U32+AN32,2) -> 509614.93 | AU32: =IFERROR(AT32/$AT$28,0) -> 0.33171235 | AZ32: =SUM(BA32:BC32) -> 39019.511 | BA32: =(Dashboard!$D$30+Dashboard!$D$31)*U32 -> 16464.881 | BB32: =Dashboard!$D$33*U32 -> 0 | BC32: =Dashboard!$D$32*U32 -> 22554.631 | BE32: =SUM(BF32:BK32) -> 5062.18 | BF32: =AF32*$AN32 -> 0 | BG32: =IF(AA32="FD",($AN32-$AC32)*AG32,AG32*$AN32) -> 2136.0644 | BH32: =IF(AB32="FD",($AN32-$AC32)*AH32,AH32*$AN32) -> 0 | BI32: =IF(AC32="FD",($AN32-$AC32)*AI32,AI32*$AN32) -> 2926.1156 | BJ32: =IF(AD32="FD",($AN32-$AC32)*AJ32,AJ32*$AN32) -> 0 | BK32: =IF(AE32="FD",($AN32-$AC32)*AK32,AK32*$AN32) -> 0 | BQ32: 1 | BR32: =22*0.05*1/3 -> 0.36666667 | BS32: 8.8 | BT32: =BQ32*BR32*BS32 -> 3.2266667 | BU32: 1 | BV32: 22 | BW32: 8.8 | BX32: =BU32*BV32*BW32 -> 193.6 | BZ32: 0 | CA32: 22 | CB32: 8.8 | CC32: =BZ32*CA32*CB32 -> 0 | CE32: 1 | CF32: =0.05*22*1/4 -> 0.275 | CG32: 8.8 | CH32: =CE32*CF32*CG32 -> 2.42 | CI32: 0 | CJ32: 22 | CK32: 8.8 | CL32: =CI32*CJ32*CK32 -> 0 | CM32: 0 | CN32: 22 | CO32: 8.8 | CP32: =CM32*CN32*CO32 -> 0 | CR32: 0 | CS32: 22 | CT32: 8.8 | CU32: =CR32*CS32*CT32 -> 0 | CV32: 0 | CW32: 22 | CX32: 8.8 | CY32: =CV32*CW32*CX32 -> 0 | CZ32: 0 | DA32: 22 | DB32: 8.8 | DC32: =CZ32*DA32*DB32 -> 0 | DE32: 0 | DF32: 22 | DG32: 8.8 | DH32: =DE32*DF32*DG32 -> 0 | DI32: 0 | DJ32: 22 | DK32: 8.8 | DL32: =DI32*DJ32*DK32 -> 0 | DM32: 0 | DN32: 22 | DO32: 8.8 | DP32: =DM32*DN32*DO32 -> 0 | DR32: 0 | DS32: 22 | DT32: 8.8 | DU32: =DR32*DS32*DT32 -> 0 | DV32: 0 | DW32: 22 | DX32: 8.8 | DY32: =DV32*DW32*DX32 -> 0 | DZ32: 0 | EA32: 22 | EB32: 8.8 | EC32: =DZ32*EA32*EB32 -> 0 | EE32: 0 | EF32: 22 | EG32: 8.8 | EH32: =EE32*EF32*EG32 -> 0 | EI32: 0 | EJ32: 22 | EK32: 8.8 | EL32: =EI32*EJ32*EK32 -> 0 | EM32: 0 | EN32: 22 | EO32: 8.8 | EP32: =EM32*EN32*EO32 -> 0 | EQ32: 0 | ER32: 22 | ES32: 8.8 | ET32: =EQ32*ER32*ES32 -> 0 | EU32: 0 | EV32: 22 | EW32: 8.8 | EX32: =EU32*EV32*EW32 -> 0 | EZ32: 4000
B33: =IFERROR(VLOOKUP(AE33,'Tabela ICMS'!$C$5:$D$32,2,0),"") | C33: =IFERROR(HLOOKUP(Dashboard!$F$9,'Tabela ICMS'!$E$3:$AF$4,2,0),"") -> 25 | E33: 2 | F33: Engenheiro Pl. de Planejamento, Qualidade e Custos ( Supervisor) - Full time | G33: mês | H33: =HISTOGRAMA!C9 -> 7 | K33: =SUMIFS(BT33:FK33,$BT$28:$FK$28,">=1",$BT$28:$FK$28,"<=18") -> 199.24667 | L33: =IFERROR(_xlfn.XLOOKUP(N33,$G$3:$G$22,$L$3:$L$22),0) -> 0 | M33: =K33*(1+L33) -> 199.24667 | N33: Equipe_02 | O33: =H33*M33 -> 1394.7267 | R33: =IFERROR(M33*VLOOKUP(N33,$G$3:$T$22,14,0),0) -> 23192.746 | S33: =H33*R33 -> 162349.22 | T33: =R33*(1+Dashboard!$D$35) -> 33932.328 | U33: =H33*T33 -> 237526.3 | X33: =SUMIFS(EZ33:FK33,$EZ$28:$FK$28,">=19",$EZ$28:$FK$28,"<=30") -> 4000 | AA33: Serviço | AB33: =X33*(1-Y33) -> 4000 | AC33: =H33*AB33 -> 28000 | AF33: {=IFERROR(INDEX('Tabela ICMS'!$E$5:$AF$32,Tarefas!B33,Tarefas!C33),0)} -> 0 | AG33: =IF(AA33="FD",(Dashboard!$D$43+Dashboard!$D$44),(Dashboard!$D$30+Dashboard!$D$31)) -> 0.0365 | AH33: =IF(AA33="FD",(Dashboard!$D$46),(Dashboard!$D$33)) -> 0 | AI33: =IF(AA33="FD",(Dashboard!$D$45),(Dashboard!$D$32)) -> 0.05 | AM33: =IF(AA33="FD",AB33*(1+Dashboard!$D$48),AB33*(1+Dashboard!$D$35)) -> 5852.2312 | AN33: =H33*AM33 -> 40965.618 | AQ33: =T33 -> 33932.328 | AR33: =AM33 -> 5852.2312 | AS33: =ROUND(T33+AM33,2) -> 39784.56 | AT33: =ROUND(U33+AN33,2) -> 278491.92 | AU33: =IFERROR(AT33/$AT$28,0) -> 0.18127257 | AZ33: =SUM(BA33:BC33) -> 20546.025 | BA33: =(Dashboard!$D$30+Dashboard!$D$31)*U33 -> 8669.7098 | BB33: =Dashboard!$D$33*U33 -> 0 | BC33: =Dashboard!$D$32*U33 -> 11876.315 | BE33: =SUM(BF33:BK33) -> 3543.526 | BF33: =AF33*$AN33 -> 0 | BG33: =IF(AA33="FD",($AN33-$AC33)*AG33,AG33*$AN33) -> 1495.2451 | BH33: =IF(AB33="FD",($AN33-$AC33)*AH33,AH33*$AN33) -> 0 | BI33: =IF(AC33="FD",($AN33-$AC33)*AI33,AI33*$AN33) -> 2048.2809 | BJ33: =IF(AD33="FD",($AN33-$AC33)*AJ33,AJ33*$AN33) -> 0 | BK33: =IF(AE33="FD",($AN33-$AC33)*AK33,AK33*$AN33) -> 0 | BQ33: 1 | BR33: =22*0.05*1/3 -> 0.36666667 | BS33: 8.8 | BT33: =BQ33*BR33*BS33 -> 3.2266667 | BU33: 0 | BV33: 22 | BW33: 8.8 | BX33: =BU33*BV33*BW33 -> 0 | BZ33: 0 | CA33: 22 | CB33: 8.8 | CC33: =BZ33*CA33*CB33 -> 0 | CE33: 1 | CF33: =0.05*22*1/4 -> 0.275 | CG33: 8.8 | CH33: =CE33*CF33*CG33 -> 2.42 | CI33: 1 | CJ33: =22 -> 22 | CK33: 8.8 | CL33: =CI33*CJ33*CK33 -> 193.6 | CM33: 0 | CN33: 22 | CO33: 8.8 | CP33: =CM33*CN33*CO33 -> 0 | CR33: 0 | CS33: 22 | CT33: 8.8 | CU33: =CR33*CS33*CT33 -> 0 | CV33: 0 | CW33: 22 | CX33: 8.8 | CY33: =CV33*CW33*CX33 -> 0 | CZ33: 0 | DA33: 22 | DB33: 8.8 | DC33: =CZ33*DA33*DB33 -> 0 | DE33: 0 | DF33: 22 | DG33: 8.8 | DH33: =DE33*DF33*DG33 -> 0 | DI33: 0 | DJ33: 22 | DK33: 8.8 | DL33: =DI33*DJ33*DK33 -> 0 | DM33: 0 | DN33: 22 | DO33: 8.8 | DP33: =DM33*DN33*DO33 -> 0 | DR33: 0 | DS33: 22 | DT33: 8.8 | DU33: =DR33*DS33*DT33 -> 0 | DV33: 0 | DW33: 22 | DX33: 8.8 | DY33: =DV33*DW33*DX33 -> 0 | DZ33: 0 | EA33: 22 | EB33: 8.8 | EC33: =DZ33*EA33*EB33 -> 0 | EE33: 0 | EF33: 22 | EG33: 8.8 | EH33: =EE33*EF33*EG33 -> 0 | EI33: 0 | EJ33: 22 | EK33: 8.8 | EL33: =EI33*EJ33*EK33 -> 0 | EM33: 0 | EN33: 22 | EO33: 8.8 | EP33: =EM33*EN33*EO33 -> 0 | EQ33: 0 | ER33: 22 | ES33: 8.8 | ET33: =EQ33*ER33*ES33 -> 0 | EU33: 0 | EV33: 22 | EW33: 8.8 | EX33: =EU33*EV33*EW33 -> 0 | EZ33: 4000
B34: =IFERROR(VLOOKUP(AE34,'Tabela ICMS'!$C$5:$D$32,2,0),"") | C34: =IFERROR(HLOOKUP(Dashboard!$F$9,'Tabela ICMS'!$E$3:$AF$4,2,0),"") -> 25 | E34: 3 | F34: Engenheiro Pl. de Planejamento, Qualidade e Custos ( Supervisor) - Full time | G34: mês | H34: =HISTOGRAMA!C10 -> 3 | K34: =SUMIFS(BT34:FK34,$BT$28:$FK$28,">=1",$BT$28:$FK$28,"<=18") -> 44.366667 | L34: =IFERROR(_xlfn.XLOOKUP(N34,$G$3:$G$22,$L$3:$L$22),0) -> 0 | M34: =K34*(1+L34) -> 44.366667 | N34: Equipe_10 | O34: =H34*M34 -> 133.1 | R34: =IFERROR(M34*VLOOKUP(N34,$G$3:$T$22,14,0),0) -> 5511.3704 | S34: =H34*R34 -> 16534.111 | T34: =R34*(1+Dashboard!$D$35) -> 8063.4533 | U34: =H34*T34 -> 24190.36 | X34: =SUMIFS(EZ34:FK34,$EZ$28:$FK$28,">=19",$EZ$28:$FK$28,"<=30") -> 4000 | AA34: Serviço | AB34: =X34*(1-Y34) -> 4000 | AC34: =H34*AB34 -> 12000 | AF34: {=IFERROR(INDEX('Tabela ICMS'!$E$5:$AF$32,Tarefas!B34,Tarefas!C34),0)} -> 0 | AG34: =IF(AA34="FD",(Dashboard!$D$43+Dashboard!$D$44),(Dashboard!$D$30+Dashboard!$D$31)) -> 0.0365 | AH34: =IF(AA34="FD",(Dashboard!$D$46),(Dashboard!$D$33)) -> 0 | AI34: =IF(AA34="FD",(Dashboard!$D$45),(Dashboard!$D$32)) -> 0.05 | AM34: =IF(AA34="FD",AB34*(1+Dashboard!$D$48),AB34*(1+Dashboard!$D$35)) -> 5852.2312 | AN34: =H34*AM34 -> 17556.693 | AQ34: =T34 -> 8063.4533 | AR34: =AM34 -> 5852.2312 | AS34: =ROUND(T34+AM34,2) -> 13915.68 | AT34: =ROUND(U34+AN34,2) -> 41747.05 | AU34: =IFERROR(AT34/$AT$28,0) -> 0.027173482 | AZ34: =SUM(BA34:BC34) -> 2092.4661 | BA34: =(Dashboard!$D$30+Dashboard!$D$31)*U34 -> 882.94814 | BB34: =Dashboard!$D$33*U34 -> 0 | BC34: =Dashboard!$D$32*U34 -> 1209.518 | BE34: =SUM(BF34:BK34) -> 1518.654 | BF34: =AF34*$AN34 -> 0 | BG34: =IF(AA34="FD",($AN34-$AC34)*AG34,AG34*$AN34) -> 640.81931 | BH34: =IF(AB34="FD",($AN34-$AC34)*AH34,AH34*$AN34) -> 0 | BI34: =IF(AC34="FD",($AN34-$AC34)*AI34,AI34*$AN34) -> 877.83467 | BJ34: =IF(AD34="FD",($AN34-$AC34)*AJ34,AJ34*$AN34) -> 0 | BK34: =IF(AE34="FD",($AN34-$AC34)*AK34,AK34*$AN34) -> 0 | BQ34: 1 | BR34: =22*0.05*1/3 -> 0.36666667 | BS34: 8.8 | BT34: =BQ34*BR34*BS34 -> 3.2266667 | BU34: 0 | BV34: 22 | BW34: 8.8 | BX34: =BU34*BV34*BW34 -> 0 | BZ34: 0 | CA34: 22 | CB34: 8.8 | CC34: =BZ34*CA34*CB34 -> 0 | CE34: 1 | CF34: =0.05*22*1/4 -> 0.275 | CG34: 8.8 | CH34: =CE34*CF34*CG34 -> 2.42 | CI34: 1 | CJ34: =20%*22 -> 4.4 | CK34: 8.8 | CL34: =CI34*CJ34*CK34 -> 38.72 | CM34: 0 | CN34: 22 | CO34: 8.8 | CP34: =CM34*CN34*CO34 -> 0 | CR34: 0 | CS34: 22 | CT34: 8.8 | CU34: =CR34*CS34*CT34 -> 0 | CV34: 0 | CW34: 22 | CX34: 8.8 | CY34: =CV34*CW34*CX34 -> 0 | CZ34: 0 | DA34: 22 | DB34: 8.8 | DC34: =CZ34*DA34*DB34 -> 0 | DE34: 0 | DF34: 22 | DG34: 8.8 | DH34: =DE34*DF34*DG34 -> 0 | DI34: 0 | DJ34: 22 | DK34: 8.8 | DL34: =DI34*DJ34*DK34 -> 0 | DM34: 0 | DN34: 22 | DO34: 8.8 | DP34: =DM34*DN34*DO34 -> 0 | DR34: 0 | DS34: 22 | DT34: 8.8 | DU34: =DR34*DS34*DT34 -> 0 | DV34: 0 | DW34: 22 | DX34: 8.8 | DY34: =DV34*DW34*DX34 -> 0 | DZ34: 0 | EA34: 22 | EB34: 8.8 | EC34: =DZ34*EA34*EB34 -> 0 | EE34: 0 | EF34: 22 | EG34: 8.8 | EH34: =EE34*EF34*EG34 -> 0 | EI34: 0 | EJ34: 22 | EK34: 8.8 | EL34: =EI34*EJ34*EK34 -> 0 | EM34: 0 | EN34: 22 | EO34: 8.8 | EP34: =EM34*EN34*EO34 -> 0 | EQ34: 0 | ER34: 22 | ES34: 8.8 | ET34: =EQ34*ER34*ES34 -> 0 | EU34: 0 | EV34: 22 | EW34: 8.8 | EX34: =EU34*EV34*EW34 -> 0 | EZ34: 4000
B35: =IFERROR(VLOOKUP(AE35,'Tabela ICMS'!$C$5:$D$32,2,0),"") | C35: =IFERROR(HLOOKUP(Dashboard!$F$9,'Tabela ICMS'!$E$3:$AF$4,2,0),"") -> 25 | E35: 4 | F35: Engenheiro Jr. Qualidade ( Supervisor) - Instalações 25% | G35: mês | H35: =HISTOGRAMA!C11 -> 5 | K35: =SUMIFS(BT35:FK35,$BT$28:$FK$28,">=1",$BT$28:$FK$28,"<=18") -> 48.4 | L35: =IFERROR(_xlfn.XLOOKUP(N35,$G$3:$G$22,$L$3:$L$22),0) -> 0 | M35: =K35*(1+L35) -> 48.4 | N35: Equipe_03 | O35: =H35*M35 -> 242 | R35: =IFERROR(M35*VLOOKUP(N35,$G$3:$T$22,14,0),0) -> 5731.8252 | S35: =H35*R35 -> 28659.126 | T35: =R35*(1+Dashboard!$D$35) -> 8385.9915 | U35: =H35*T35 -> 41929.957 | X35: =SUMIFS(EZ35:FK35,$EZ$28:$FK$28,">=19",$EZ$28:$FK$28,"<=30") -> 3000 | AA35: Serviço | AB35: =X35*(1-Y35) -> 3000 | AC35: =H35*AB35 -> 15000 | AF35: {=IFERROR(INDEX('Tabela ICMS'!$E$5:$AF$32,Tarefas!B35,Tarefas!C35),0)} -> 0 | AG35: =IF(AA35="FD",(Dashboard!$D$43+Dashboard!$D$44),(Dashboard!$D$30+Dashboard!$D$31)) -> 0.0365 | AH35: =IF(AA35="FD",(Dashboard!$D$46),(Dashboard!$D$33)) -> 0 | AI35: =IF(AA35="FD",(Dashboard!$D$45),(Dashboard!$D$32)) -> 0.05 | AM35: =IF(AA35="FD",AB35*(1+Dashboard!$D$48),AB35*(1+Dashboard!$D$35)) -> 4389.1734 | AN35: =H35*AM35 -> 21945.867 | AQ35: =T35 -> 8385.9915 | AR35: =AM35 -> 4389.1734 | AS35: =ROUND(T35+AM35,2) -> 12775.16 | AT35: =ROUND(U35+AN35,2) -> 63875.82 | AU35: =IFERROR(AT35/$AT$28,0) -> 0.041577272 | AZ35: =SUM(BA35:BC35) -> 3626.9413 | BA35: =(Dashboard!$D$30+Dashboard!$D$31)*U35 -> 1530.4434 | BB35: =Dashboard!$D$33*U35 -> 0 | BC35: =Dashboard!$D$32*U35 -> 2096.4979 | BE35: =SUM(BF35:BK35) -> 1898.3175 | BF35: =AF35*$AN35 -> 0 | BG35: =IF(AA35="FD",($AN35-$AC35)*AG35,AG35*$AN35) -> 801.02414 | BH35: =IF(AB35="FD",($AN35-$AC35)*AH35,AH35*$AN35) -> 0 | BI35: =IF(AC35="FD",($AN35-$AC35)*AI35,AI35*$AN35) -> 1097.2933 | BJ35: =IF(AD35="FD",($AN35-$AC35)*AJ35,AJ35*$AN35) -> 0 | BK35: =IF(AE35="FD",($AN35-$AC35)*AK35,AK35*$AN35) -> 0 | BQ35: 0 | BR35: 0 | BS35: 8.8 | BT35: =BQ35*BR35*BS35 -> 0 | BU35: 0 | BV35: 22 | BW35: 8.8 | BX35: =BU35*BV35*BW35 -> 0 | BZ35: 0 | CA35: 22 | CB35: 8.8 | CC35: =BZ35*CA35*CB35 -> 0 | CE35: 0 | CF35: 0 | CG35: 8.8 | CH35: =CE35*CF35*CG35 -> 0 | CI35: 0 | CJ35: 22 | CK35: 8.8 | CL35: =CI35*CJ35*CK35 -> 0 | CM35: 1 | CN35: =22*25% -> 5.5 | CO35: 8.8 | CP35: =CM35*CN35*CO35 -> 48.4 | CR35: 0 | CS35: 22 | CT35: 8.8 | CU35: =CR35*CS35*CT35 -> 0 | CV35: 0 | CW35: 22 | CX35: 8.8 | CY35: =CV35*CW35*CX35 -> 0 | CZ35: 0 | DA35: 22 | DB35: 8.8 | DC35: =CZ35*DA35*DB35 -> 0 | DE35: 0 | DF35: 22 | DG35: 8.8 | DH35: =DE35*DF35*DG35 -> 0 | DI35: 0 | DJ35: 22 | DK35: 8.8 | DL35: =DI35*DJ35*DK35 -> 0 | DM35: 0 | DN35: 22 | DO35: 8.8 | DP35: =DM35*DN35*DO35 -> 0 | DR35: 0 | DS35: 22 | DT35: 8.8 | DU35: =DR35*DS35*DT35 -> 0 | DV35: 0 | DW35: 22 | DX35: 8.8 | DY35: =DV35*DW35*DX35 -> 0 | DZ35: 0 | EA35: 22 | EB35: 8.8 | EC35: =DZ35*EA35*EB35 -> 0 | EE35: 0 | EF35: 22 | EG35: 8.8 | EH35: =EE35*EF35*EG35 -> 0 | EI35: 0 | EJ35: 22 | EK35: 8.8 | EL35: =EI35*EJ35*EK35 -> 0 | EM35: 0 | EN35: 22 | EO35: 8.8 | EP35: =EM35*EN35*EO35 -> 0 | EQ35: 0 | ER35: 22 | ES35: 8.8 | ET35: =EQ35*ER35*ES35 -> 0 | EU35: 0 | EV35: 22 | EW35: 8.8 | EX35: =EU35*EV35*EW35 -> 0 | EZ35: =4000*0+3000 -> 3000
